<?xml version="1.0" encoding="UTF-8"?>
<!-- Generated by org.testng.reporters.JUnitReportReporter -->
<testsuite hostname="DESKTOP-K0SFL7M" failures="0" tests="18" name="Test.Ancera.Reports.CoccidiaLog" time="1391.461" errors="5" timestamp="2021-11-05T15:13:17 PKT" skipped="3">
  <testcase classname="Test.Ancera.Reports.CoccidiaLog" name="NavigateCoccidia" time="10.712"/>
  <system-out/>
  <testcase classname="Test.Ancera.Reports.CoccidiaLog" name="DateFilter" time="90.315">
    <error message="java.lang.AssertionError: The following asserts failed:
	did not expect [120] but found [120]" type="java.lang.Exception">
      <![CDATA[java.lang.Exception: java.lang.AssertionError: The following asserts failed:
did not expect [120] but found [120]
at Test.Ancera.Reports.CoccidiaLog.DateFilter(CoccidiaLog.java:255)
at java.base/jdk.internal.reflect.NativeMethodAccessorImpl.invoke0(Native Method)
at java.base/jdk.internal.reflect.NativeMethodAccessorImpl.invoke(NativeMethodAccessorImpl.java:64)
at java.base/jdk.internal.reflect.DelegatingMethodAccessorImpl.invoke(DelegatingMethodAccessorImpl.java:43)
at java.base/java.lang.reflect.Method.invoke(Method.java:564)
at org.testng.internal.MethodInvocationHelper.invokeMethod(MethodInvocationHelper.java:132)
at org.testng.internal.TestInvoker.invokeMethod(TestInvoker.java:599)
at org.testng.internal.TestInvoker.invokeTestMethod(TestInvoker.java:174)
at org.testng.internal.MethodRunner.runInSequence(MethodRunner.java:46)
at org.testng.internal.TestInvoker$MethodInvocationAgent.invoke(TestInvoker.java:822)
at org.testng.internal.TestInvoker.invokeTestMethods(TestInvoker.java:147)
at org.testng.internal.TestMethodWorker.invokeTestMethods(TestMethodWorker.java:146)
at org.testng.internal.TestMethodWorker.run(TestMethodWorker.java:128)
at java.base/java.util.ArrayList.forEach(ArrayList.java:1511)
at org.testng.TestRunner.privateRun(TestRunner.java:764)
at org.testng.TestRunner.run(TestRunner.java:585)
at org.testng.SuiteRunner.runTest(SuiteRunner.java:384)
at org.testng.SuiteRunner.runSequentially(SuiteRunner.java:378)
at org.testng.SuiteRunner.privateRun(SuiteRunner.java:337)
at org.testng.SuiteRunner.run(SuiteRunner.java:286)
at org.testng.SuiteRunnerWorker.runSuite(SuiteRunnerWorker.java:53)
at org.testng.SuiteRunnerWorker.run(SuiteRunnerWorker.java:96)
at org.testng.TestNG.runSuitesSequentially(TestNG.java:1218)
at org.testng.TestNG.runSuitesLocally(TestNG.java:1140)
at org.testng.TestNG.runSuites(TestNG.java:1069)
at org.testng.TestNG.run(TestNG.java:1037)
at org.testng.remote.AbstractRemoteTestNG.run(AbstractRemoteTestNG.java:115)
at org.testng.remote.RemoteTestNG.initAndRun(RemoteTestNG.java:251)
at org.testng.remote.RemoteTestNG.main(RemoteTestNG.java:77)
Caused by: java.lang.AssertionError: The following asserts failed:
did not expect [120] but found [120]
at org.testng.asserts.SoftAssert.assertAll(SoftAssert.java:47)
at org.testng.asserts.SoftAssert.assertAll(SoftAssert.java:31)
at Test.Ancera.Reports.CoccidiaLog.DateFilter(CoccidiaLog.java:251)
... 28 more
]]>
    </error>
  </testcase> <!-- DateFilter -->
  <system-out/>
  <testcase classname="Test.Ancera.Reports.CoccidiaLog" name="DateLockFilter" time="21.076"/>
  <system-out/>
  <testcase classname="Test.Ancera.Reports.CoccidiaLog" name="TestFilter" time="238.954">
    <error message="java.lang.AssertionError: expected [1] but found [0]" type="java.lang.Exception">
      <![CDATA[java.lang.Exception: java.lang.AssertionError: expected [1] but found [0]
at Test.Ancera.Reports.CoccidiaLog.TestFilter(CoccidiaLog.java:463)
at java.base/jdk.internal.reflect.NativeMethodAccessorImpl.invoke0(Native Method)
at java.base/jdk.internal.reflect.NativeMethodAccessorImpl.invoke(NativeMethodAccessorImpl.java:64)
at java.base/jdk.internal.reflect.DelegatingMethodAccessorImpl.invoke(DelegatingMethodAccessorImpl.java:43)
at java.base/java.lang.reflect.Method.invoke(Method.java:564)
at org.testng.internal.MethodInvocationHelper.invokeMethod(MethodInvocationHelper.java:132)
at org.testng.internal.TestInvoker.invokeMethod(TestInvoker.java:599)
at org.testng.internal.TestInvoker.invokeTestMethod(TestInvoker.java:174)
at org.testng.internal.MethodRunner.runInSequence(MethodRunner.java:46)
at org.testng.internal.TestInvoker$MethodInvocationAgent.invoke(TestInvoker.java:822)
at org.testng.internal.TestInvoker.invokeTestMethods(TestInvoker.java:147)
at org.testng.internal.TestMethodWorker.invokeTestMethods(TestMethodWorker.java:146)
at org.testng.internal.TestMethodWorker.run(TestMethodWorker.java:128)
at java.base/java.util.ArrayList.forEach(ArrayList.java:1511)
at org.testng.TestRunner.privateRun(TestRunner.java:764)
at org.testng.TestRunner.run(TestRunner.java:585)
at org.testng.SuiteRunner.runTest(SuiteRunner.java:384)
at org.testng.SuiteRunner.runSequentially(SuiteRunner.java:378)
at org.testng.SuiteRunner.privateRun(SuiteRunner.java:337)
at org.testng.SuiteRunner.run(SuiteRunner.java:286)
at org.testng.SuiteRunnerWorker.runSuite(SuiteRunnerWorker.java:53)
at org.testng.SuiteRunnerWorker.run(SuiteRunnerWorker.java:96)
at org.testng.TestNG.runSuitesSequentially(TestNG.java:1218)
at org.testng.TestNG.runSuitesLocally(TestNG.java:1140)
at org.testng.TestNG.runSuites(TestNG.java:1069)
at org.testng.TestNG.run(TestNG.java:1037)
at org.testng.remote.AbstractRemoteTestNG.run(AbstractRemoteTestNG.java:115)
at org.testng.remote.RemoteTestNG.initAndRun(RemoteTestNG.java:251)
at org.testng.remote.RemoteTestNG.main(RemoteTestNG.java:77)
Caused by: java.lang.AssertionError: expected [1] but found [0]
at org.testng.Assert.fail(Assert.java:99)
at org.testng.Assert.failNotEquals(Assert.java:1037)
at org.testng.Assert.assertEqualsImpl(Assert.java:140)
at org.testng.Assert.assertEquals(Assert.java:122)
at org.testng.Assert.assertEquals(Assert.java:907)
at org.testng.Assert.assertEquals(Assert.java:917)
at Test.Ancera.Reports.CoccidiaLog.TestFilter(CoccidiaLog.java:448)
... 28 more
]]>
    </error>
  </testcase> <!-- TestFilter -->
  <system-out/>
  <testcase classname="Test.Ancera.Reports.CoccidiaLog" name="SiteName" time="20.939"/>
  <system-out/>
  <testcase classname="Test.Ancera.Reports.CoccidiaLog" name="Contexual" time="245.711">
    <error message="java.lang.AssertionError: did not expect [Showing 1 - 1 Results] but found [Showing 1 - 1 Results]" type="java.lang.Exception">
      <![CDATA[java.lang.Exception: java.lang.AssertionError: did not expect [Showing 1 - 1 Results] but found [Showing 1 - 1 Results]
at Test.Ancera.Reports.CoccidiaLog.Contexual(CoccidiaLog.java:822)
at java.base/jdk.internal.reflect.NativeMethodAccessorImpl.invoke0(Native Method)
at java.base/jdk.internal.reflect.NativeMethodAccessorImpl.invoke(NativeMethodAccessorImpl.java:64)
at java.base/jdk.internal.reflect.DelegatingMethodAccessorImpl.invoke(DelegatingMethodAccessorImpl.java:43)
at java.base/java.lang.reflect.Method.invoke(Method.java:564)
at org.testng.internal.MethodInvocationHelper.invokeMethod(MethodInvocationHelper.java:132)
at org.testng.internal.TestInvoker.invokeMethod(TestInvoker.java:599)
at org.testng.internal.TestInvoker.invokeTestMethod(TestInvoker.java:174)
at org.testng.internal.MethodRunner.runInSequence(MethodRunner.java:46)
at org.testng.internal.TestInvoker$MethodInvocationAgent.invoke(TestInvoker.java:822)
at org.testng.internal.TestInvoker.invokeTestMethods(TestInvoker.java:147)
at org.testng.internal.TestMethodWorker.invokeTestMethods(TestMethodWorker.java:146)
at org.testng.internal.TestMethodWorker.run(TestMethodWorker.java:128)
at java.base/java.util.ArrayList.forEach(ArrayList.java:1511)
at org.testng.TestRunner.privateRun(TestRunner.java:764)
at org.testng.TestRunner.run(TestRunner.java:585)
at org.testng.SuiteRunner.runTest(SuiteRunner.java:384)
at org.testng.SuiteRunner.runSequentially(SuiteRunner.java:378)
at org.testng.SuiteRunner.privateRun(SuiteRunner.java:337)
at org.testng.SuiteRunner.run(SuiteRunner.java:286)
at org.testng.SuiteRunnerWorker.runSuite(SuiteRunnerWorker.java:53)
at org.testng.SuiteRunnerWorker.run(SuiteRunnerWorker.java:96)
at org.testng.TestNG.runSuitesSequentially(TestNG.java:1218)
at org.testng.TestNG.runSuitesLocally(TestNG.java:1140)
at org.testng.TestNG.runSuites(TestNG.java:1069)
at org.testng.TestNG.run(TestNG.java:1037)
at org.testng.remote.AbstractRemoteTestNG.run(AbstractRemoteTestNG.java:115)
at org.testng.remote.RemoteTestNG.initAndRun(RemoteTestNG.java:251)
at org.testng.remote.RemoteTestNG.main(RemoteTestNG.java:77)
Caused by: java.lang.AssertionError: did not expect [Showing 1 - 1 Results] but found [Showing 1 - 1 Results]
at org.testng.Assert.fail(Assert.java:99)
at org.testng.Assert.failEquals(Assert.java:1041)
at org.testng.Assert.assertNotEqualsImpl(Assert.java:147)
at org.testng.Assert.assertNotEquals(Assert.java:1531)
at org.testng.Assert.assertNotEquals(Assert.java:1535)
at Test.Ancera.Reports.CoccidiaLog.Contexual(CoccidiaLog.java:804)
... 28 more
]]>
    </error>
  </testcase> <!-- Contexual -->
  <system-out/>
  <testcase classname="Test.Ancera.Reports.CoccidiaLog" name="CoccidiaLock" time="322.143"/>
  <system-out/>
  <testcase classname="Test.Ancera.Reports.CoccidiaLog" name="Pagination" time="12.882"/>
  <system-out/>
  <testcase classname="Test.Ancera.Reports.CoccidiaLog" name="RowsPerPage" time="7.409"/>
  <system-out/>
  <testcase classname="Test.Ancera.Reports.CoccidiaLog" name="AllignmentTest" time="0.797"/>
  <system-out/>
  <testcase classname="Test.Ancera.Reports.CoccidiaLog" name="FieldAccessResetDefault" time="6.460"/>
  <system-out/>
  <testcase classname="Test.Ancera.Reports.CoccidiaLog" name="PNGExport" time="23.634"/>
  <system-out/>
  <testcase classname="Test.Ancera.Reports.CoccidiaLog" name="CSVExport" time="188.878">
    <error message="Expected condition failed: waiting for alert to be present (tried for 180 second(s) with 500 milliseconds interval)
Build info: version: &#039;4.0.0-alpha-7&#039;, revision: &#039;de8579b6d5&#039;
System info: host: &#039;DESKTOP-K0SFL7M&#039;, ip: &#039;192.168.56.1&#039;, os.name: &#039;Windows 10&#039;, os.arch: &#039;amd64&#039;, os.version: &#039;10.0&#039;, java.version: &#039;15.0.2&#039;
Driver info: org.openqa.selenium.support.events.EventFiringWebDriver
Capabilities {acceptInsecureCerts: false, browserName: chrome, browserVersion: 94.0.4606.81, chrome: {chromedriverVersion: 94.0.4606.61 (418b78f5838ed..., userDataDir: C:\Users\User\AppData\Local...}, goog:chromeOptions: {debuggerAddress: localhost:58853}, javascriptEnabled: true, networkConnectionEnabled: false, pageLoadStrategy: normal, platform: WINDOWS, platformName: WINDOWS, proxy: Proxy(), setWindowRect: true, strictFileInteractability: false, timeouts: {implicit: 0, pageLoad: 300000, script: 30000}, unhandledPromptBehavior: dismiss and notify, webauthn:extension:credBlob: true, webauthn:extension:largeBlob: true, webauthn:virtualAuthenticators: true}
Session ID: 8d17c693117a466bd67ff54ada5aaee4" type="org.openqa.selenium.TimeoutException">
      <![CDATA[org.openqa.selenium.TimeoutException: Expected condition failed: waiting for alert to be present (tried for 180 second(s) with 500 milliseconds interval)
Build info: version: '4.0.0-alpha-7', revision: 'de8579b6d5'
System info: host: 'DESKTOP-K0SFL7M', ip: '192.168.56.1', os.name: 'Windows 10', os.arch: 'amd64', os.version: '10.0', java.version: '15.0.2'
Driver info: org.openqa.selenium.support.events.EventFiringWebDriver
Capabilities {acceptInsecureCerts: false, browserName: chrome, browserVersion: 94.0.4606.81, chrome: {chromedriverVersion: 94.0.4606.61 (418b78f5838ed..., userDataDir: C:\Users\User\AppData\Local...}, goog:chromeOptions: {debuggerAddress: localhost:58853}, javascriptEnabled: true, networkConnectionEnabled: false, pageLoadStrategy: normal, platform: WINDOWS, platformName: WINDOWS, proxy: Proxy(), setWindowRect: true, strictFileInteractability: false, timeouts: {implicit: 0, pageLoad: 300000, script: 30000}, unhandledPromptBehavior: dismiss and notify, webauthn:extension:credBlob: true, webauthn:extension:largeBlob: true, webauthn:virtualAuthenticators: true}
Session ID: 8d17c693117a466bd67ff54ada5aaee4
at org.openqa.selenium.support.ui.FluentWait.until(FluentWait.java:211)
at Test.Ancera.Reports.CoccidiaLog.CSVExport(CoccidiaLog.java:1523)
at java.base/jdk.internal.reflect.NativeMethodAccessorImpl.invoke0(Native Method)
at java.base/jdk.internal.reflect.NativeMethodAccessorImpl.invoke(NativeMethodAccessorImpl.java:64)
at java.base/jdk.internal.reflect.DelegatingMethodAccessorImpl.invoke(DelegatingMethodAccessorImpl.java:43)
at java.base/java.lang.reflect.Method.invoke(Method.java:564)
at org.testng.internal.MethodInvocationHelper.invokeMethod(MethodInvocationHelper.java:132)
at org.testng.internal.TestInvoker.invokeMethod(TestInvoker.java:599)
at org.testng.internal.TestInvoker.invokeTestMethod(TestInvoker.java:174)
at org.testng.internal.MethodRunner.runInSequence(MethodRunner.java:46)
at org.testng.internal.TestInvoker$MethodInvocationAgent.invoke(TestInvoker.java:822)
at org.testng.internal.TestInvoker.invokeTestMethods(TestInvoker.java:147)
at org.testng.internal.TestMethodWorker.invokeTestMethods(TestMethodWorker.java:146)
at org.testng.internal.TestMethodWorker.run(TestMethodWorker.java:128)
at java.base/java.util.ArrayList.forEach(ArrayList.java:1511)
at org.testng.TestRunner.privateRun(TestRunner.java:764)
at org.testng.TestRunner.run(TestRunner.java:585)
at org.testng.SuiteRunner.runTest(SuiteRunner.java:384)
at org.testng.SuiteRunner.runSequentially(SuiteRunner.java:378)
at org.testng.SuiteRunner.privateRun(SuiteRunner.java:337)
at org.testng.SuiteRunner.run(SuiteRunner.java:286)
at org.testng.SuiteRunnerWorker.runSuite(SuiteRunnerWorker.java:53)
at org.testng.SuiteRunnerWorker.run(SuiteRunnerWorker.java:96)
at org.testng.TestNG.runSuitesSequentially(TestNG.java:1218)
at org.testng.TestNG.runSuitesLocally(TestNG.java:1140)
at org.testng.TestNG.runSuites(TestNG.java:1069)
at org.testng.TestNG.run(TestNG.java:1037)
at org.testng.remote.AbstractRemoteTestNG.run(AbstractRemoteTestNG.java:115)
at org.testng.remote.RemoteTestNG.initAndRun(RemoteTestNG.java:251)
at org.testng.remote.RemoteTestNG.main(RemoteTestNG.java:77)
]]>
    </error>
  </testcase> <!-- CSVExport -->
  <system-out/>
  <testcase classname="Test.Ancera.Reports.CoccidiaLog" name="CSVAuditExport" time="189.593">
    <error message="Expected condition failed: waiting for alert to be present (tried for 180 second(s) with 500 milliseconds interval)
Build info: version: &#039;4.0.0-alpha-7&#039;, revision: &#039;de8579b6d5&#039;
System info: host: &#039;DESKTOP-K0SFL7M&#039;, ip: &#039;192.168.56.1&#039;, os.name: &#039;Windows 10&#039;, os.arch: &#039;amd64&#039;, os.version: &#039;10.0&#039;, java.version: &#039;15.0.2&#039;
Driver info: org.openqa.selenium.support.events.EventFiringWebDriver
Capabilities {acceptInsecureCerts: false, browserName: chrome, browserVersion: 94.0.4606.81, chrome: {chromedriverVersion: 94.0.4606.61 (418b78f5838ed..., userDataDir: C:\Users\User\AppData\Local...}, goog:chromeOptions: {debuggerAddress: localhost:58853}, javascriptEnabled: true, networkConnectionEnabled: false, pageLoadStrategy: normal, platform: WINDOWS, platformName: WINDOWS, proxy: Proxy(), setWindowRect: true, strictFileInteractability: false, timeouts: {implicit: 0, pageLoad: 300000, script: 30000}, unhandledPromptBehavior: dismiss and notify, webauthn:extension:credBlob: true, webauthn:extension:largeBlob: true, webauthn:virtualAuthenticators: true}
Session ID: 8d17c693117a466bd67ff54ada5aaee4" type="org.openqa.selenium.TimeoutException">
      <![CDATA[org.openqa.selenium.TimeoutException: Expected condition failed: waiting for alert to be present (tried for 180 second(s) with 500 milliseconds interval)
Build info: version: '4.0.0-alpha-7', revision: 'de8579b6d5'
System info: host: 'DESKTOP-K0SFL7M', ip: '192.168.56.1', os.name: 'Windows 10', os.arch: 'amd64', os.version: '10.0', java.version: '15.0.2'
Driver info: org.openqa.selenium.support.events.EventFiringWebDriver
Capabilities {acceptInsecureCerts: false, browserName: chrome, browserVersion: 94.0.4606.81, chrome: {chromedriverVersion: 94.0.4606.61 (418b78f5838ed..., userDataDir: C:\Users\User\AppData\Local...}, goog:chromeOptions: {debuggerAddress: localhost:58853}, javascriptEnabled: true, networkConnectionEnabled: false, pageLoadStrategy: normal, platform: WINDOWS, platformName: WINDOWS, proxy: Proxy(), setWindowRect: true, strictFileInteractability: false, timeouts: {implicit: 0, pageLoad: 300000, script: 30000}, unhandledPromptBehavior: dismiss and notify, webauthn:extension:credBlob: true, webauthn:extension:largeBlob: true, webauthn:virtualAuthenticators: true}
Session ID: 8d17c693117a466bd67ff54ada5aaee4
at org.openqa.selenium.support.ui.FluentWait.until(FluentWait.java:211)
at Test.Ancera.Reports.CoccidiaLog.CSVAuditExport(CoccidiaLog.java:1606)
at java.base/jdk.internal.reflect.NativeMethodAccessorImpl.invoke0(Native Method)
at java.base/jdk.internal.reflect.NativeMethodAccessorImpl.invoke(NativeMethodAccessorImpl.java:64)
at java.base/jdk.internal.reflect.DelegatingMethodAccessorImpl.invoke(DelegatingMethodAccessorImpl.java:43)
at java.base/java.lang.reflect.Method.invoke(Method.java:564)
at org.testng.internal.MethodInvocationHelper.invokeMethod(MethodInvocationHelper.java:132)
at org.testng.internal.TestInvoker.invokeMethod(TestInvoker.java:599)
at org.testng.internal.TestInvoker.invokeTestMethod(TestInvoker.java:174)
at org.testng.internal.MethodRunner.runInSequence(MethodRunner.java:46)
at org.testng.internal.TestInvoker$MethodInvocationAgent.invoke(TestInvoker.java:822)
at org.testng.internal.TestInvoker.invokeTestMethods(TestInvoker.java:147)
at org.testng.internal.TestMethodWorker.invokeTestMethods(TestMethodWorker.java:146)
at org.testng.internal.TestMethodWorker.run(TestMethodWorker.java:128)
at java.base/java.util.ArrayList.forEach(ArrayList.java:1511)
at org.testng.TestRunner.privateRun(TestRunner.java:764)
at org.testng.TestRunner.run(TestRunner.java:585)
at org.testng.SuiteRunner.runTest(SuiteRunner.java:384)
at org.testng.SuiteRunner.runSequentially(SuiteRunner.java:378)
at org.testng.SuiteRunner.privateRun(SuiteRunner.java:337)
at org.testng.SuiteRunner.run(SuiteRunner.java:286)
at org.testng.SuiteRunnerWorker.runSuite(SuiteRunnerWorker.java:53)
at org.testng.SuiteRunnerWorker.run(SuiteRunnerWorker.java:96)
at org.testng.TestNG.runSuitesSequentially(TestNG.java:1218)
at org.testng.TestNG.runSuitesLocally(TestNG.java:1140)
at org.testng.TestNG.runSuites(TestNG.java:1069)
at org.testng.TestNG.run(TestNG.java:1037)
at org.testng.remote.AbstractRemoteTestNG.run(AbstractRemoteTestNG.java:115)
at org.testng.remote.RemoteTestNG.initAndRun(RemoteTestNG.java:251)
at org.testng.remote.RemoteTestNG.main(RemoteTestNG.java:77)
]]>
    </error>
  </testcase> <!-- CSVAuditExport -->
  <system-out/>
  <testcase classname="Test.Ancera.Reports.CoccidiaLog" name="TemplateExport" time="11.958"/>
  <system-out/>
  <testcase classname="Test.Ancera.Reports.CoccidiaLog" name="FieldAccess">
    <skipped/>
  </testcase> <!-- FieldAccess -->
  <system-out/>
  <testcase classname="Test.Ancera.Reports.CoccidiaLog" name="Sorting">
    <skipped/>
  </testcase> <!-- Sorting -->
  <system-out/>
  <testcase classname="Test.Ancera.Reports.CoccidiaLog" name="wildcard">
    <skipped/>
  </testcase> <!-- wildcard -->
  <system-out/>
</testsuite> <!-- Test.Ancera.Reports.CoccidiaLog -->
